Workbook

Sheet README
A1: ZapWise reference database
A3: Purpose | B3: Numbers behind the ZapWise migration estimate. Edit here, then run export_assets.py to refresh the app JSON.
A4: Compiled | B4: 2026-10-14
A5: Blue text | B5: Typed values. Change these when you have a better measurement or source.
A6: Black text | B6: Formulas. Do not overwrite.
A7: Status VERIFIED | B7: Number read on the cited page.
A8: Status SECONDARY | B8: Distributor page, Wikipedia or a similar secondary page.
A9: Status DERIVED | B9: Computed from verified inputs; the note shows how.
A10: Status ASSUMPTION | B10: A modelling choice. It must be stated in the report and tested where possible.
A11: Status UNVERIFIED | B11: Commonly cited but not confirmed on a primary page. Replace before the final submission if you can.
A12: Sources | B12: The Sources sheet numbers every reference (S01...). Other sheets cite those numbers.
A13: Checklist | B13: Student_Checklist lists the measurements that would replace the weakest assumptions.
A14: Sheets | B14: Sources, Polymers, Substances, Groups, Alt_References, Contents, Measured, Containers, FoodClasses, KpfModel, ModelParams, BodyWeights, Products, RecipeSteps, WattTables, Literature, Validation, Models, Student_Checklist

Sheet Sources
A1: ID | B1: Citation | C1: URL | D1: Type | E1: Accessed
A2: S01 | B2: Simoneau C. (ed.) et al. (2010). Applicability of generally recognised diffusion models for the estimation of specific migration in support of EU Directive 2002/72/EC. JRC59476, EUR 24514 EN. | C2: https://publications.jrc.ec.europa.eu/repository/bitstream/JRC59476/reqno_jrc59476_mathmod_v10_cs_2010_09_24_final.pdf%5B1%5D.pdf | D2: report | E2: 2026-10-14
A3: S02 | B3: Haldimann M. et al. (2013). Exposure to antimony from polyethylene terephthalate (PET) trays used in ready-to-eat meals. Food Addit Contam A 30(3):587-598. doi:10.1080/19440049.2012.751631 | C3: https://pmc.ncbi.nlm.nih.gov/articles/PMC3613973/ | D3: paper | E3: 2026-10-14
A4: S03 | B4: Liu J-M. et al. (2020). Phthalate esters in commercial disposable lunch boxes (title to confirm). Food Sci Nutr. doi:10.1002/fsn3.1863 | C4: https://pmc.ncbi.nlm.nih.gov/articles/PMC7590312 | D4: paper | E4: 2026-10-14
A5: S04 | B5: Lan M., Li H., Ying G. (2022). Phthalate esters in PP food containers and their migration (title to confirm). J South China Normal Univ (Nat Sci) 54(2):52-62. doi:10.6054/j.jscnun.2022026 | C5: https://doi.org/10.6054/j.jscnun.2022026 | D5: paper | E5: 2026-10-14
A6: S05 | B6: Moreira M.A., Andre L.C., Cardeal Z.L. (2014). Analysis of phthalate migration to food simulants in plastic containers during microwave operations. IJERPH 11(1):507-526. doi:10.3390/ijerph110100507 | C6: https://www.mdpi.com/1660-4601/11/1/507/html | D6: paper | E6: 2026-10-14
A7: S06 | B7: Review of antimony in PET bottles (2023, title to confirm). Molecules 28(20):7166. | C7: https://www.mdpi.com/1420-3049/28/20/7166 | D7: paper | E7: 2026-10-14
A8: S07 | B8: EFSA CEP Panel (2019). Update of the risk assessment of DBP, BBP, DEHP, DINP and DIDP for use in food contact materials. EFSA Journal 17(12):5838. | C8: https://doaj.org/article/cad5a51311ba4452b9b5807ddfb881a9 | D8: agency | E8: 2026-10-14
A9: S08 | B9: Commission Regulation (EU) 2023/1442 amending Annex I to Regulation (EU) No 10/2011 (phthalates, group restriction 36). | C9: https://eur-lex.europa.eu/legal-content/EN/TXT/HTML/?uri=CELEX:32023R1442 | D9: regulation | E9: 2026-10-14
A10: S09 | B10: WHO (2022). Antimony in drinking-water, chemical fact sheet (TDI 6 ug/kg bw/day, 2003 assessment). | C10: https://cdn.who.int/media/docs/default-source/wash-documents/water-safety-and-quality/chemical-fact-sheets-2022/antimony-fact-sheet-2022.pdf | D10: agency | E10: 2026-10-14
A11: S10 | B11: US EPA IRIS. Di(2-ethylhexyl)phthalate (DEHP), oral RfD 0.02 mg/kg-day (1987). | C11: https://iris.epa.gov/ChemicalLanding/&substance_nmbr=14 | D11: agency | E11: 2026-10-14
A12: S11 | B12: EFSA Scientific Committee (2012). Default values for body weight (adult 70 kg, toddler 12 kg, infant 5 kg). | C12: https://www.efsa.europa.eu/en/press/news/120307a | D12: agency | E12: 2026-10-14
... A83: S82 | B83: BfR (2019). Do not use 'bamboo ware' tableware for hot drinks and meals. Press release, 25 November 2019 (melamine-formaldehyde resin with bamboo fibre filler; not for heating food in the microwave). | C83: https://www.bfr.bund.de/en/press-release/do-not-use-bamboo-ware-tableware-for-hot-drinks-and-meals/ | D83: agency | E83: 2026-10-14

Sheet Polymers
A1: Key | B1: Polymer | C1: A_P' | D1: tau (K) | E1: T max valid (C) | F1: Density (g/cm3) | G1: Density status | H1: Density source | I1: Piringer source | J1: Status | K1: Huang 2017 material | L1: Huang b | M1: Huang tau (K) | N1: Partition material (Huang and Jolliet 2019)
A2: LDPE | B2: Low-density polyethylene | C2: 11.5 | D2: 0 | E2: 80 | F2: 0.92 | G2: SECONDARY | H2: S21 | I2: S01 | J2: VERIFIED | K2: Polyethylene (PE, LDPE, LLDPE) | L2: -1.65 | M2: 0 | N2: Low-density polyethylene (LDPE)
A3: LLDPE | B3: Linear low-density polyethylene | C3: 11.5 | D3: 0 | E3: 100 | F3: 0.92 | G3: SECONDARY | H3: S21 | I3: S01 | J3: VERIFIED | K3: Polyethylene (PE, LDPE, LLDPE) | L3: -1.65 | M3: 0 | N3: Linear low-density polyethylene (LLDPE)
A4: HDPE | B4: High-density polyethylene | C4: 14.5 | D4: 1577 | E4: 90 | F4: 0.95 | G4: ASSUMPTION | I4: S01 | J4: VERIFIED | K4: High density polyethylene (HDPE) | L4: 5.11 | M4: -2391 | N4: High-density polyethylene (HDPE)
A5: PP | B5: Polypropylene (homo and random) | C5: 13.1 | D5: 1577 | E5: 120 | F5: 0.9 | G5: VERIFIED | H5: S18 | I5: S01 | J5: VERIFIED | K5: PP homopolymer | L5: 4.53 | M5: -2391 | N5: Polypropylene (PP) homopolymer
A6: PP_RUBBER | B6: Polypropylene (rubber-modified) | C6: 11.5 | D6: 0 | E6: 100 | F6: 0.9 | G6: VERIFIED | H6: S18 | I6: S01 | J6: VERIFIED | K6: PP copolymer | L6: 4.79 | M6: -2391 | N6: Ethylene-propylene copolymer
A7: PS | B7: Polystyrene (GPPS) | C7: -1 | D7: 0 | E7: 70 | F7: 1.05 | G7: SECONDARY | H7: S21 | I7: S01 | J7: VERIFIED | K7: General polystyrene (PS) | L7: 2.04 | M7: -2391 | N7: Polystyrene (PS)
A8: HIPS | B8: High-impact polystyrene | C8: 1 | D8: 0 | E8: 70 | F8: 1.05 | G8: SECONDARY | H8: S21 | I8: S01 | J8: VERIFIED | K8: High-impact polystyrene (HIPS) | L8: -7.11 | M8: 0 | N8: Polystyrene (PS)
A9: PET_HI | B9: PET above Tg (about 70 C) | C9: 6.4 | D9: 1577 | E9: 175 | F9: 1.35 | G9: VERIFIED | H9: S02 | I9: S01;S41 | J9: VERIFIED | K9: Polyethylene terephthalate (PET) | L9: 0 | M9: -2391 | N9: Polyethylene terephthalate (PET)
A10: PET_LO | B10: PET below Tg | C10: 3.1 | D10: 1577 | E10: 70 | F10: 1.35 | G10: VERIFIED | H10: S02 | I10: S01;S41 | J10: VERIFIED | K10: Polyethylene terephthalate (PET) | L10: 0 | M10: -2391 | N10: Polyethylene terephthalate (PET)
A11: PEN | B11: Polyethylene naphthalate | C11: 5 | D11: 1577 | E11: 175 | I11: S01 | J11: VERIFIED | K11: Polyethylene naphthalate (PEN) | L11: -1.16 | M11: -2391 | N11: Polyethylene terephthalate (PET)
A12: PA6 | B12: Polyamide 6 | C12: 0 | D12: 0 | E12: 100 | I12: S01 | J12: VERIFIED | K12: Polyamide (PA) | L12: -5.4 | M12: 0 | N12: Nylon 6
A13: PA66 | B13: Polyamide 6,6 | C13: 2 | D13: 0 | E13: 100 | I13: S01 | J13: VERIFIED | K13: Polyamide (PA) | L13: -5.4 | M13: 0 | N13: Nylon 6
A14: PVC_RIGID | B14: Rigid PVC | C14: -1 | D14: 0 | E14: 70 | I14: S01 | J14: VERIFIED | K14: Rigid polymers | L14: -11.9 | M14: 1676 | N14: Polyvinyl chloride (PVC)
A16: Two diffusion coefficients per polymer. The engine works between them on a log scale (ModelParams d_weight_*).
A17: Piringer upper bound (cm2/s): D_P = 1e4 * exp(A_P' - tau/T - 0.1351*Mr^(2/3) + 0.003*Mr - 10454/T) [S01]
A18: Huang 2017 QPPR, realistic (m2/s): log10 D = 6.39 -2.49 log10 MW + b + (tau -3486)/T; x 1e4 for cm2/s [S78]
A19: Example: DEHP (Mr 390.57) in PP at 100 C
A20: Piringer (cm2/s) | F20: =10000*EXP(INDEX(C2:C14,MATCH("PP",A2:A14,0))-INDEX(D2:D14,MATCH("PP",A2:A14,0))/373.15-0.1351*390.57^(2/3)+0.003*390.57-10454/373.15) -> 1.1500359e-07 | G20: cm2/s
A21: Huang 2017 (cm2/s) | F21: =10000*10^(6.39-2.49*LOG10(390.57)+INDEX(L2:L14,MATCH("PP",A2:A14,0))+(INDEX(M2:M14,MATCH("PP",A2:A14,0))-3486)/373.15) -> 5.2116024e-08 | G21: cm2/s
A22: Piringer / Huang | F22: =F20/F21 -> 2.2066839

Sheet Substances
A1: Key | B1: Name | C1: CAS | D1: MW (g/mol) | E1: log Kow | F1: Group | G1: RPF (DEHP-eq) | H1: Diffusion model | I1: D0 (cm2/s) | J1: Ea (kJ/mol) | K1: Diffusible fraction | L1: Status | M1: Sources | N1: Note
A2: DEHP | B2: Di(2-ethylhexyl) phthalate | C2: 117-81-7 | D2: 390.57 | E2: 7.5 | F2: phthalate_dehp_eq | G2: 1 | H2: piringer | K2: 1 | L2: VERIFIED | M2: S13;S08 | N2: log Kow 7.14 also reported (ECHA via Health Canada). Sets the partition coefficient through the Huang and Jolliet 2019 regression [S76].
A3: DBP | B3: Dibutyl phthalate | C3: 84-74-2 | D3: 278.3 | E3: 4.46 | F3: phthalate_dehp_eq | G3: 5 | H3: piringer | K3: 1 | L3: VERIFIED | M3: S14;S08 | N3: RPF 5 from the DEHP-equivalent formula of group restriction 36.
A4: DIBP | B4: Diisobutyl phthalate | C4: 84-69-5 | D4: 278.3 | E4: 4.11 | F4: phthalate_dehp_eq | G4: 4 | H4: piringer | K4: 1 | L4: RPF VERIFIED; MW DERIVED (isomer of DBP, C16H22O4); log Kow UNVERIFIED (commonly cited 4.11) | M4: S08 | N4: log Kow sets the partition coefficient through the Huang and Jolliet 2019 regression [S76]. Confirm 4.11 on PubChem or ECHA.
A5: BBP | B5: Benzyl butyl phthalate | C5: 85-68-7 | D5: 312.3 | E5: 4.91 | F5: phthalate_dehp_eq | G5: 0.1 | H5: piringer | K5: 1 | L5: VERIFIED | M5: S14;S08 | N5: Not detected in microwaved PP containers [S05]; kept for completeness.
A6: SB | B6: Antimony (catalyst residue in PET) | C6: 7440-36-0 | D6: 121.76 | F6: antimony | G6: 1 | H6: arrhenius | I6: 360000000000000 | J6: 188 | K6: 0.62 | L6: VERIFIED (D0, Ea, diffusible fraction) | M6: S02 | N6: Fitted by Haldimann 2013 on CPET at 120-150 C; use at 100-125 C is a short extrapolation. Piringer is not designed for metal species.
A7: I168 | B7: Irgafos 168 (phosphite antioxidant in PP) | C7: 31570-04-4 | D7: 646.94 | E7: 15.5 | F7: antioxidant_i168 | G7: 1 | H7: piringer | K7: 1 | L7: MW SECONDARY; log Kow ESTIMATED (XlogP3-AA 15.5) | M7: S53;S54;S80 | N7: No measured log Kow exists for this very hydrophobic additive. The engine caps log Kow at the highest value measured in the partition data for the food's EtOH-eq band, so the estimate only matters for fatty foods. The FDA ADI also covers its oxidised phosphate.
A9: Antimony D(100 C) from Haldimann 2013 Arrhenius fit (cm2/s): | I9: =I6*EXP(-J6*1000/(8.314462618*373.15)) -> 1.7378834e-12

Sheet Groups
A1: Key | B1: Label (en) | C1: Label (ko) | D1: TDI | E1: Unit | F1: Agency | G1: Year | H1: Daily allowance, 70 kg adult (ug) | I1: Status | J1: Sources | K1: Basis
A2: phthalate_dehp_eq | B2: Phthalates | C2: 프탈레이트(DEHP 당량) | D2: 50 | E2: ug/kg bw/day | F2: EFSA | G2: 2019 | H2: =D2*70 -> 3500 | I2: VERIFIED | J2: S07;S08 | K2: Group TDI, reduction in fetal testosterone; DEHP-eq = 1 DEHP + 5 DBP + 4 DIBP + 0.1 BBP (Reg. 2023/1442 group 36). Temporary TDI.
A3: antimony | B3: Antimony | C3: 안티모니 | D3: 6 | E3: ug/kg bw/day | F3: WHO | G3: 2003 | H3: =D3*70 -> 420 | I3: VERIFIED | J3: S09 | K3: NOAEL 6.0 mg/kg bw/day (90-day rat study) / UF 1000.
A4: antioxidant_i168 | B4: Irgafos 168 (antioxidant) | C4: 산화방지제 Irgafos 168 | D4: 1000 | E4: ug/kg bw/day (ADI) | F4: US FDA | G4: 2021 | H4: =D4*70 -> 70000 | I4: VERIFIED | J4: S53 | K4: NOEL 2000 ppm in a 2-year rat study, safety factor 100; covers Irgafos 168 and its phosphate.
A5: lead | B5: Lead | C5: 납(EFSA 기준점) | D5: 0.5 | E5: ug/kg bw/day (BMDL01) | F5: EFSA | G5: 2010 | H5: =D5*70 -> 35 | I5: VERIFIED | J5: S52 | K5: No safe intake exists for lead, so EFSA withdrew the tolerable weekly intake and uses a benchmark dose (developmental neurotoxicity in children, BMDL01). The % shown is of this reference point, not of a safe limit.

Sheet Alt_References
A1: Substance | B1: Agency | C1: Value | D1: Unit | E1: Year | F1: Status | G1: Sources
A2: DEHP | B2: US EPA IRIS | C2: 20 | D2: ug/kg bw/day (oral RfD) | E2: 1987 | F2: VERIFIED | G2: S10
A3: DBP | B3: EFSA | C3: 10 | D3: ug/kg bw/day (individual t-TDI) | E3: 2019 | F3: VERIFIED | G3: S07
A4: BBP | B4: EFSA | C4: 500 | D4: ug/kg bw/day (individual t-TDI) | E4: 2019 | F4: VERIFIED | G4: S07
A5: DINP | B5: EFSA | C5: 150 | D5: ug/kg bw/day (individual t-TDI) | E5: 2019 | F5: VERIFIED | G5: S07
A6: BPA | B6: EFSA | C6: 0.0002 | D6: ug/kg bw/day (0.2 ng/kg bw/day) | E6: 2023 | F6: VERIFIED | G6: S12

Sheet Contents
A1: Material | B1: Substance | C1: Low (mg/kg) | D1: High (mg/kg) | E1: Central (mg/kg) | F1: Distribution | G1: Status | H1: Sources | I1: Note
A2: PP | B2: DBP | C2: 0 | D2: 2.83 | E2: =(C2+D2)/2 -> 1.415 | F2: uniform | G2: VERIFIED (range of reported values) | H2: S03;S04 | I2: Liu 2020 1.39-2.83 mg/kg; Lan 2022 ND-0.995 mg/kg (unit printed mg/g in abstract, read as ug/g). Not an intended PP additive.
A3: PP | B3: DIBP | C3: 0.237 | D3: 1.84 | E3: =(C3+D3)/2 -> 1.0385 | F3: uniform | G3: VERIFIED (range of reported values) | H3: S03;S04 | I3: Lan 2022 0.237-1.676 (100% detected); Liu 2020 0.53-1.84 mg/kg.
A4: PP | B4: DEHP | C4: 0 | D4: 2.302 | E4: =(C4+D4)/2 -> 1.151 | F4: uniform | G4: VERIFIED (unit UNVERIFIED) | H4: S04 | I4: Lan 2022 ND-2.302, detection rate 78%.
A5: CPET | B5: SB | C5: 100 | D5: 400 | E5: =(C5+D5)/2 -> 250 | F5: uniform | G5: VERIFIED | H5: S06;S02 | I5: PET range 100-400 mg/kg (review). The one CPET tray measured by Haldimann 2013 had 290-318 mg/kg, inside this range.
A6: PET_COAT | B6: SB | C6: 100 | D6: 400 | E6: =(C6+D6)/2 -> 250 | F6: uniform | G6: ASSUMPTION | H6: S06 | I6: No measurement for PET-coated board; the PET range is applied to the coating layer.
A7: PP | B7: I168 | C7: 166.47 | D7: 845.27 | E7: =(C7+D7)/2 -> 505.87 | F7: uniform | G7: VERIFIED for PP films; ASSUMPTION for rigid PP | H7: S54 | I7: Six PP food packaging films. Rigid PP containers also carry phosphite antioxidants; no rigid-container value was found.
A8: PP_FILM | B8: I168 | C8: 166.47 | D8: 845.27 | E8: =(C8+D8)/2 -> 505.87 | F8: uniform | G8: VERIFIED | H8: S54 | I8: PP film sealant layer of steam bags and pouches.

Sheet Measured
A1: Container | B1: Substance | C1: Group | D1: Low | E1: Middle | F1: High | G1: Unit | H1: Basis | I1: Conditions | J1: Status | K1: Sources
A2: paper_cup | B2: Lead (Pb) | C2: lead | D2: 0.583 | E2: 1.38 | F2: 22.9 | G2: ug/kg | H2: per_kg_food | I2: 20 PE-lined paper cups, 200 mL ultrapure water at 95-100 C, 15 min. Value per litre of water applied per kg of soup or noodles. | J2: VERIFIED | K2: S51
A4: Used when a container has status measured: intake = value x food mass (per_kg_food) or value (per_item); range = low to high.

Sheet Containers
A1: Key | B1: Label (en) | C1: Label (ko) | D1: Status | E1: Content key | F1: Polymer | G1: Density (g/cm3) | H1: Thickness (cm) | I1: Thickness low | J1: Thickness high | K1: Contact area at 300 g (cm2) | L1: Form | M1: Max use (C) | N1: Max use (F) | O1: Reason (en) | P1: Reason (ko) | Q1: Sources | R1: Notes | S1: Contact mode
A2: cpet_tray | B2: Black oven tray (#1) | C2: 검은 오븐 겸용 트레이(CPET) | D2: ok | E2: CPET | F2: PET_HI | G2: 1.35 | H2: 0.031 | I2: 0.025 | J2: 0.06 | K2: 290 | L2: tray | M2: 204 | N2: =IF(M2="","",M2*9/5+32) -> 399.2 | Q2: S02;S16;S17 | R2: Thickness and density of the tray measured by Haldimann 2013. Max use 400 F (Sabert). | S2: wall
A3: pp_container | B3: Microwave-safe plastic (#5) | C3: 전자레인지용 플라스틱 용기(PP 5번) | D3: ok | E3: PP | F3: PP | G3: 0.9 | H3: 0.05 | I3: 0.03 | J3: 0.06 | K3: 250 | L3: bowl | M3: 104 | N3: =IF(M3="","",M3*9/5+32) -> 219.2 | Q3: S18;S19 | R3: Thickness 0.3-0.6 mm is UNVERIFIED; measure with calipers. Max use 220 F per Inline Plastics 2023 (240 F in 2020 catalog). | S3: wall
A4: pet_board_tray | B4: Coated paper tray | C4: PET 코팅 종이 트레이(오븐 겸용) | D4: ok | E4: PET_COAT | F4: PET_HI | G4: 1.35 | H4: 0.0029 | I4: 0.002 | J4: 0.004 | K4: 290 | L4: tray | M4: 220 | N4: =IF(M4="","",M4*9/5+32) -> 428 | Q4: S60;S06 | R4: PET coating 40 g/m2, about 29 um, usable to 220 C (Holmen). Ovenable paperboard trays carry a PET coating; antimony content of the coating is assumed equal to PET (ASSUMPTION). | S4: wall
A5: paperboard_tray | B5: Paper plate or fiber tray | C5: 종이·압착 섬유 트레이(코팅 미확인) | D5: info | K5: 290 | L5: tray | M5: 204 | N5: =IF(M5="","",M5*9/5+32) -> 399.2 | O5: The old worry was PFAS coatings, which US food packaging dropped in 2024. | P5: 코팅 없는 종이·섬유 트레이의 주요 우려 물질은 기름 방지용 PFAS였다. 미국에서는 2024년 2월부터 PFAS 기름 방지제가 식품 포장용으로 팔리지 않고, 캘리포니아는 총 유기 플루오린을 100 ppm 미만으로 제한한다. 현재 미국 제품에는 없어야 하므로 숫자는 보여 주지 않는다. | Q5: S63;S75;S62 | R5: Detail: The main chemical concern for uncoated or fibre trays was PFAS grease-proofing. PFAS grease-proofing agents are no longer sold for US food packaging (FDA, Feb 2024) and California limits total organic fluorine to 100 ppm. No number is shown because current US trays should not contain them. If the tray is marked PET or dual-ovenable, use pet_board_tray. | S5: wall
A6: paper_cup | B6: Paper cup or bowl | C6: 종이 컵·그릇(PE 코팅) | D6: measured | F6: LDPE | G6: 0.92 | H6: 0.00163 | K6: 210 | L6: cup | M6: 70 | N6: =IF(M6="","",M6*9/5+32) -> 158 | O6: It's lined with a thin plastic film. Lab tests found traces of lead in hot water from these cups. | P6: 측정값 기반 추정이다. PE 코팅 종이컵 20종에 끓는 물을 붓고 15분 둔 실험에서 납이 나왔다(중앙값 1.38, 범위 0.58~22.9 µg/L). | Q6: S51;S52;S59 | R6: Detail: Estimated from measured migration: 20 PE-lined paper cups filled with near-boiling water for 15 min released lead (median 1.38, range 0.58-22.9 ug/L). PE coating 15 g/m2 (about 16 um). No additive content of the PE layer itself was found, so the diffusion model is not used. Fast-food paper cups showed no fluorine (PFAS) in a US survey. | S6: wall
A7: steam_bag | B7: Steam bag | C7: 스팀 백(PP 실런트 필름) | D7: ok | E7: PP_FILM | F7: PP | G7: 0.9 | H7: 0.0064 | I7: 0.0032 | J7: 0.0095 | K7: 400 | L7: bag | M7: 120 | N7: =IF(M7="","",M7*9/5+32) -> 248 | Q7: S55;S54 | R7: Patent structure PET 12 um / adhesive / PE or PP skin / PP core 19-63.5 um / PP-PE sealant 12.7-31.8 um (food side). PP layers on the food side total 32-95 um. Patent bag of frozen vegetables reached 95-102 C in 4 min. | S7: steam
A8: pouch | B8: Microwave pouch | C8: 전자레인지 파우치(CPP 실런트) | D8: ok | E8: PP_FILM | F8: PP | G8: 0.9 | H8: 0.0075 | I8: 0.006 | J8: 0.00875 | K8: 300 | L8: bag | M8: 120 | N8: =IF(M8="","",M8*9/5+32) -> 248 | Q8: S56;S57;S54;S58 | R8: Microwavable retort pouches use PET (often AlOx or SiOx coated) / nylon / CPP 60-87.5 um on the food side. Retorted pouches were already heated to 121-135 C in the factory; a study found 4,4'-MDA (aromatic amine from adhesive) at 2.7-3.1 ug/kg after retort in two brands, above the EU 2 ug/kg limit. | S8: wall
A9: takeout_tub | B9: Take-out tub | C9: 배달·마가린 용기 | D9: block | E9: PP | F9: PP | G9: 0.9 | H9: 0.05 | I9: 0.03 | J9: 0.06 | K9: 250 | L9: bowl | M9: 104 | N9: =IF(M9="","",M9*9/5+32) -> 219.2 | O9: Not made for heat. It can warp or melt. | P9: FSIS는 배달 용기와 마가린 통이 전자레인지에서 휘거나 녹을 수 있다고 안내한다. | Q9: S22 | R9: Detail: FSIS says take-out and margarine tubs can warp or melt in the microwave. | S9: wall
A10: pet_clamshell | B10: Clear clamshell (#1) | C10: 투명 뚜껑 일체형 용기(PET 1번) | D10: block | F10: PET_LO | G10: 1.33 | K10: 250 | L10: tray | M10: 60 | N10: =IF(M10="","",M10*9/5+32) -> 140 | O10: It softens around 150°F, cooler than reheated food. | P10: APET는 65~69 °C 부근에서 물러지므로 재가열 온도를 견디지 못한다. | Q10: S20;S19 | S10: wall
A11: eps_foam | B11: Foam tray or cup | C11: 스티로폼 용기(EPS) | D11: block | F11: PS | K11: 250 | L11: tray | M11: 70 | N11: =IF(M11="","",M11*9/5+32) -> 158 | O11: Not made for heat. It can warp or melt. | P11: FSIS는 스티로폼 트레이가 고온에서 안정하지 않으므로 쓰지 말라고 안내한다. | Q11: S22;S01 | R11: Piringer PS parameters are valid only up to 70 C. | S11: wall
A12: ps_rigid | B12: Clear hard plastic (#6) | C12: 투명 PS 용기(6번) | D12: block | F12: PS | G12: 1.05 | K12: 250 | L12: tray | M12: 77 | N12: =IF(M12="","",M12*9/5+32) -> 170.6 | O12: It's only made for up to 170°F. Reheated food gets hotter. | P12: OPS의 사용 온도 상한은 170 °F(77 °C)이다. | Q12: S19 | S12: wall
A13: metal | B13: Metal or foil | C13: 금속·호일 용기 | D13: block | L13: tray | N13: =IF(M13="","",M13*9/5+32) | O13: Metal can spark in the microwave. | P13: 금속은 전자레인지에서 불꽃이 튈 수 있다. 접시에 옮겨 담는다. | Q13: S44;S45 | R13: Detail: Metal can spark in a microwave. Move the food to a plate. | S13: wall
A14: melamine | B14: Melamine or bamboo dish | C14: 멜라민·대나무 섬유 식기 | D14: block | L14: bowl | N14: =IF(M14="","",M14*9/5+32) | O14: Not for hot food or the microwave. Heat can make it release chemicals. | P14: 대나무 섬유 식기는 멜라민-폼알데하이드 수지에 대나무 섬유를 섞은 것이다. 뜨거운 음식으로 멜라민과 폼알데하이드가 나올 수 있어 BfR은 전자레인지 가열에 쓰지 말라고 권고한다 [S82]. 접시에 옮겨 담는다. | Q14: S82 | R14: Detail: 'Bamboo' tableware is melamine-formaldehyde resin with bamboo fibre; hot food can draw melamine and formaldehyde out of it, and BfR advises against heating food in it in the microwave [S82]. Move the food to a plate. Added after a bamboo-fibre bowl turned up in the store photos (2026-10-14). | S14: wall
A15: glass | B15: Glass dish | C15: 유리 그릇 | D15: inert | L15: bowl | N15: =IF(M15="","",M15*9/5+32) | O15: No plastic touches your food. | P15: 음식이 플라스틱에 닿지 않는다. | Q15: S22 | R15: FSIS: use cookware made for microwave use. | S15: wall
A16: ceramic | B16: Plate or bowl | C16: 도자기 접시·그릇 | D16: inert | L16: plate | N16: =IF(M16="","",M16*9/5+32) | O16: No plastic touches your food. Skip plates with gold or silver trim. | P16: 음식이 플라스틱에 닿지 않는다. 금테 접시는 피한다. | Q16: S22;S44 | S16: wall
A17: stove_pot | B17: Pot on the stove | C17: 냄비(가스레인지) | D17: inert | L17: pot | N17: =IF(M17="","",M17*9/5+32) | O17: The food comes out of the package, so no plastic gets heated. | P17: 가열 전에 음식을 포장에서 꺼낸다. | S17: wall
A18: popcorn_bag | B18: Popcorn bag | C18: 전자레인지 팝콘 봉투 | D18: info | L18: bag | N18: =IF(M18="","",M18*9/5+32) | O18: US popcorn bags no longer use PFAS coatings. | P18: 예전 팝콘 봉투에는 기름 방지용 PFAS가 쓰였다. FDA 연구에서 봉투 속 PFOA가 6~290 µg/kg이었고, 튀긴 뒤 기름에서 플루오로텔로머 코팅 물질이 2.1 mg/kg 나왔다. Conagra는 2022년 Act II 봉투에서 PFAS를 뺐다고 밝혔고, 미국에서는 2024년부터 PFAS 기름 방지제가 팔리지 않는다. 현재 봉투에는 숫자를 보여 주지 않는다. | Q18: S64;S65;S63 | R18: Detail: Older popcorn bags used PFAS grease-proofing: an FDA study found PFOA at 6-290 ug/kg in bags and a fluorotelomer coating chemical at 2.1 mg/kg in oil after popping. Conagra says it removed PFAS from Act II bags in 2022, and PFAS grease-proofing agents are no longer sold in the US (2024). No number is shown for current bags. Susceptor (metallised PET) reaches over 200 C; models for 100 C do not apply. | S18: wall
A19: susceptor_sleeve | B19: Crisping sleeve | C19: 크리스핑 슬리브(서셉터) | D19: info | L19: sleeve | N19: =IF(M19="","",M19*9/5+32) | O19: These get much hotter than boiling, so I can't estimate them. | P19: Hot Pockets는 2024년에 크리스핑 슬리브를 없앴다. 1992년 영국 연구에서 서셉터 위에서 조리한 피자에서 에폭시 접착제 성분 BADGE가 0.1~0.7 mg/kg 나왔다. 서셉터는 100 °C보다 훨씬 뜨거워지므로 앱은 이를 모델로 계산하지 않는다. | Q19: S66;S67 | R19: Detail: Hot Pockets removed crisping sleeves in 2024. A 1992 UK study found the epoxy adhesive component BADGE at 0.1-0.7 mg/kg in pizza cooked on susceptors. Susceptors run far hotter than 100 C, so the app does not model them. BADGE TDI 0.15 mg/kg bw/day (EFSA 2004) is UNVERIFIED in this build, so no percentage is computed. | S19: wall

Sheet FoodClasses
A1: Class | B1: Fat fraction min | C1: Fat fraction max | D1: Partition rule | E1: EtOH-eq low (%) | F1: EtOH-eq high (%) | G1: Contact T cap low (C) | H1: Contact T cap high (C) | I1: Status | J1: Sources | K1: Note
A2: lean | B2: 0 | C2: 0.03 | D2: EtOH-eq uniform 10-60 %; log Kpf from the Huang and Jolliet 2019 regression | E2: 10 | F2: 60 | G2: 100 | H2: 100 | I2: ASSUMPTION (EtOH-eq range anchored to simulant A and dataset assignments) | J2: S81;S76 | K2: Watery foods. EU simulant A (10 % ethanol) for aqueous food; the partition dataset assigns fruit juices 40 % and milk with 1.5-3 % fat 60 %. Contact temperature capped at boiling.
A3: medium | B3: 0.03 | C3: 0.1 | D3: EtOH-eq uniform 50-80 %; log Kpf from the Huang and Jolliet 2019 regression | E3: 50 | F3: 80 | G3: 100 | H3: 110 | I3: ASSUMPTION | J3: S81;S76;S28 | K3: Sauces, cheese, emulsions. EU simulant D1 (50 % ethanol) covers oil-in-water emulsions and dairy; the upper end allows for free fat in cheese sauces.
A4: fatty | B4: 0.1 | C4: 1 | D4: EtOH-eq uniform 80-100 %; log Kpf from the Huang and Jolliet 2019 regression | E4: 80 | F4: 100 | G4: 105 | H4: 125 | I4: ASSUMPTION (EtOH-eq anchored to the 95 % ethanol substitute for oil) | J4: S81;S76;S29;S30 | K4: Fat-rich foods. EU rules accept 95 % ethanol as a substitute test for vegetable oil (D2). Fat-rich foods heat faster than water and oil can pass 100 C; HK CFS tested fatty food at 120 C.
A6: EtOH-eq is the ethanol share (v/v) of a water-ethanol mixture that dissolves migrants like the food does. It feeds the partition regression on the KpfModel sheet [S76, S77]. Antimony (inorganic) uses K = 1 [S01].

Sheet KpfModel
A1: Coefficient | B1: Value | C1: Term
A2: b0 | B2: -1.36 | C2: Intercept
A3: b_kow | B3: 1.06 | C3: log Kow
A4: b_etoh | B4: -0.014 | C4: EtOH-eq (%)
A5: b_kow_etoh | B5: -0.0066 | C5: log Kow x EtOH-eq
A6: b_invt | B6: 866 | C6: (1/T - 1/298.15), T in K
A8: Material offsets (log10 units)
A9: Material | B9: Offset
A10: Average HDPE/LDPE | B10: 0.15
A11: Carbohydrates | B11: -0.55
A12: Ethylene-propylene copolymer | B12: -0.11
A13: Ethylene-vinyl acetate copolymer (EVA) | B13: 0.58
A14: High-density polyethylene (HDPE) | B14: 0.035
A15: Ionomer (Surlyn 1652, 1702) | B15: -0.027
A16: Linear low-density polyethylene (LLDPE) | B16: -1.21
A17: Low-density polyethylene (LDPE) | B17: 0
A18: Nylon 6 | B18: -0.92
A19: Poly 2-hydroxyethylmethacrylate | B19: 0.39
A20: Polycaprolactone related polymers | B20: 0.85
A21: Polydimethylsiloxane (PDMS) | B21: 0.01
... A28: Starch, Cellulose | B28: -1.83
A30: Applicability domain: highest measured log Kow per EtOH-eq band (the engine caps log Kow here)
A31: EtOH-eq from (%) | B31: EtOH-eq to (%) | C31: log Kow min | D31: log Kow max | E31: Rows
A32: 0 | B32: 20 | C32: 0.38 | D32: 8.91 | E32: 881
A33: 20 | B33: 60 | C33: 0.35 | D33: 10.16 | E33: 421
A34: 60 | B34: 90 | C34: 1.36 | D34: 11.15 | E34: 263
A35: 90 | B35: 100 | C35: 0.32 | D35: 18.104941 | E35: 316
A37: Example: DEHP (log Kow 7.5) in PP homopolymer, lean food (EtOH-eq 35 %), 100 C
A38: log10 Kpf | B38: =B2+B3*7.5+B4*35+B5*7.5*35+B6*(1/373.15-1/298.15)+INDEX(B10:B28,MATCH("Polypropylene (PP) homopolymer",A10:A28,0)) -> 3.2837043
A39: Old rule (v0.2) used log10 K = 3 for every lipophilic migrant in lean food.
A41: log10 Kpf = b0 + b_kow*logKow + b_etoh*EtOH + b_kow_etoh*logKow*EtOH + b_invt*(1/T - 1/298.15) + material offset
A42: Kpf = concentration in polymer / concentration in food (volume basis); EtOH in % v/v; T in K
A43: Residual SD 0.79 log10 units. RMSE of the refitted regression when each chemical is held out (GroupKFold by CAS); whole-study hold-out gives 1.11. Sources S76, S79.

Sheet ModelParams
A1: Key | B1: Value | C1: Unit | D1: Status | E1: Sources | F1: Note
A2: T0_frozen_C | B2: -18 | C2: C | D2: ASSUMPTION | F2: Home freezer temperature (0 F).
A3: T0_chilled_C | B3: 4 | C3: C | D3: ASSUMPTION | F3: Refrigerator temperature (40 F).
A4: T0_shelf_C | B4: 20 | C4: C | D4: ASSUMPTION | F4: Room temperature for shelf-stable cups, bowls and pouches.
A5: water_fraction | B5: 0.75 | C5: g/g | D5: UNVERIFIED | F5: Typical frozen meal water content 70-80 %; replace per product with USDA FoodData Central values.
A6: c_water | B6: 4.187 | C6: J/(g K) | D6: VERIFIED | E6: S27 | F6: Specific heat of liquid water.
A7: c_solids | B7: 1.8 | C7: J/(g K) | D7: UNVERIFIED | F7: Specific heat of food solids (protein, fat, carbohydrate are roughly 1.5-2.0).
A8: c_frozen | B8: 2.05 | C8: J/(g K) | D8: VERIFIED (illustrative) | E8: S27 | F8: Frozen food heat capacity used in the worked example of S27.
A9: latent_heat_water | B9: 333.57 | C9: J/g | D9: VERIFIED | E9: S27 | F9: Latent heat of fusion of water; multiplied by water_fraction.
A10: T_target_avg_C | B10: 85 | C10: C | D10: ASSUMPTION | E10: S22 | F10: Average food temperature reached when the label recipe ends. FSIS requires at least 165 F (74 C) at the coldest point, so the average is set above it.
A11: T_boil_C | B11: 100 | C11: C | D11: VERIFIED | E11: S31 | F11: Watery food cannot pass 100 C at 1 atm.
A12: edge_excess_C | B12: 15 | C12: C | D12: ASSUMPTION | E12: S28 | F12: Food next to the container wall is hotter than the average. Jung 2022 saw edges at 100 C while the rest stayed below 80 C.
A13: edge_excess_low_C | B13: 10 | C13: C | D13: ASSUMPTION | E13: S28 | F13: Monte Carlo lower bound.
A14: edge_excess_high_C | B14: 20 | C14: C | D14: ASSUMPTION | E14: S28 | F14: Monte Carlo upper bound.
A15: power_factor_low | B15: 0.85 | C15: - | D15: VERIFIED | E15: S26 | F15: Real output of a rated oven, lower bound (about -15 %).
A16: power_factor_high | B16: 1.15 | C16: - | D16: VERIFIED | E16: S26 | F16: Upper bound (+15 %).
A17: area_factor_low | B17: 0.8 | C17: - | D17: ASSUMPTION | F17: Contact area uncertainty.
A18: area_factor_high | B18: 1.2 | C18: - | D18: ASSUMPTION | F18: Contact area uncertainty.
A19: area_ref_mass_g | B19: 300 | C19: g | D19: ASSUMPTION | F19: Reference food mass for the container area values; area scales with (mass/300)^(2/3).
A20: food_density | B20: 1 | C20: g/cm3 | D20: ASSUMPTION | E20: S27 | F20: S27 uses 1.05 in its example.
A21: default_ref_watt | B21: 1100 | C21: W | D21: ASSUMPTION | E21: S25 | F21: Used when a label gives times without a wattage; 13 of 15 seed labels with a single reference use 1100 W.
A22: eat_minutes | B22: 10 | C22: min | D22: ASSUMPTION | F22: Time the food sits in the container while being eaten.
A23: eat_end_C | B23: 50 | C23: C | D23: ASSUMPTION | F23: Food temperature at the end of eating.
A24: dt_s | B24: 1 | C24: s | D24: ASSUMPTION | F24: Time step of the temperature-diffusion integration.
A25: short_time_Fo | B25: 0.05 | C25: - | D25: ASSUMPTION | E25: S01 | F25: Below this Fourier number the semi-infinite (short-time) Crank solution is used.
A26: mc_samples | B26: 300 | C26: - | D26: ASSUMPTION | F26: Monte Carlo samples per evaluation.
A27: mc_seed | B27: 20261026 | C27: - | D27: ASSUMPTION | F27: Fixed seed so results are reproducible.
A28: band_low_pct | B28: 2 | C28: % TDI | D28: DERIVED | E28: S08 | F28: Below this the meal uses under one tenth of the 20 % of the TDI that EU rules allocate to food contact materials.
A29: band_high_pct | B29: 10 | C29: % TDI | D29: DERIVED | E29: S08 | F29: At or above this one meal uses half of the 20 % allocation.
A30: daily_alert_pct | B30: 20 | C30: % TDI | D30: DERIVED | E30: S08 | F30: Daily packaging share equal to the EU allocation factor (20 % of the TDI).
A31: steam_onset_fraction | B31: 0.6 | C31: - | D31: ASSUMPTION | E31: S55 | F31: Steam bags: once this share of the label energy is delivered, the film sits in steam at 100 C. A patent steam bag reached 95-102 C after 4 min of a 5-6 min cook; the generic wall model gave only 46 C (validation V6).
A32: energy_short_ratio | B32: 0.95 | C32: - | D32: ASSUMPTION | E32: S22 | F32: Below 95 % of the label energy the app warns the food may not reach 165 F.
A33: R_gas | B33: 8.3144626 | C33: J/(mol K) | D33: VERIFIED | F33: Gas constant (CODATA).
A34: d_weight_central | B34: 0.5 | C34: - | D34: ASSUMPTION | E34: S78;S01 | F34: Position between the realistic diffusion coefficient (Huang 2017 QPPR, 0) and the regulatory upper bound (Piringer, 1) on a log scale. 0.5 is the log midpoint.
A35: d_weight_low | B35: 0 | C35: - | D35: ASSUMPTION | E35: S78 | F35: Monte Carlo lower end: Huang 2017 QPPR value.
A36: d_weight_high | B36: 1 | C36: - | D36: ASSUMPTION | E36: S01 | F36: Monte Carlo upper end: Piringer upper bound.
A37: kpf_resid_sd | B37: 0.79 | C37: log10 | D37: DERIVED | E37: S76 | F37: Prediction error of the partition regression when each chemical is held out (ml/train_kpf.py, GroupKFold by CAS). Monte Carlo adds a normal error with this SD.
A38: kpf_t_ref_K | B38: 298.15 | C38: K | D38: VERIFIED | E38: S76 | F38: Reference temperature of the partition regression.

Sheet BodyWeights
A1: Group | B1: Body weight (kg) | C1: Status | D1: Sources | E1: Note
A2: adult | B2: 70 | C2: VERIFIED | D2: S11 | E2: EFSA default adult body weight.
A3: adult_eu_fcm | B3: 60 | C3: VERIFIED | D3: S31 | E3: Convention behind EU specific migration limits (60 kg eating 1 kg food).
A4: teen | B4: 55 | C4: ASSUMPTION | E4: Placeholder for ages 13-17; the user should enter real weight.
A5: child | B5: 30 | C5: ASSUMPTION | E5: Placeholder for ages 8-12; the user should enter real weight.
A6: toddler | B6: 12 | C6: VERIFIED | D6: S11 | E6: EFSA default toddler body weight.

Sheet Products
A1: ID | B1: Brand | C1: Product | D1: UPC | E1: Category | F1: Net (oz) | G1: Net (g, label) | H1: Net (g) | I1: Servings | J1: Serving (g) | K1: Fat per serving (g) | L1: Added water (g) | M1: Food mass (g) | N1: Fat fraction | O1: Fat class | P1: Storage | Q1: Container key | R1: Container confidence | S1: Container note | T1: Reference watt | U1: Instructions | V1: Do not microwave | W1: Low-watt note | X1: Do-not statements | Y1: Oven directions | Z1: Container description | AA1: Data flags | AB1: Source URLs
A2: zw-001 | B2: Banquet | C2: Mega Bowls Mike's Hot Honey Chicken Mac 'N Cheese | D2: 031000008550 | E2: frozen_tray | F2: 13.8 | G2: 392 | H2: =IF(G2<>"",G2,IF(F2<>"",ROUND(F2*28.3495,0),"")) -> 392 | I2: 1 | J2: 392 | K2: 25 | L2: 0 | M2: =IF(H2="","",H2+L2) -> 392 | N2: =IF(OR(K2="",M2=""),"",IF(J2<>"",K2/J2*H2/M2,IF(I2<>"",K2*I2/M2,""))) -> 0.06377551 | O2: =IF(N2="","",IF(N2<FoodClasses!$C$2,"lean",IF(N2<FoodClasses!$C$3,"medium","fatty"))) -> medium | P2: frozen | Q2: cpet_tray | R2: inferred | S2: Same tray goes into a 375 F oven, which plastic other than CPET does not survive. | T2: 1100 | U2: complete | V2: no | W2: None given. Label says appliances vary and to adjust times. | X2: Do not prepare in toaster oven | Cook only one at a time | Keep frozen, do not thaw | Y2: 375°F, vent film, on baking sheet 45 min, stand 2 min, stir. | Z2: Film-covered bowl tray; same tray is used in the 375°F oven per the directions. Material not stated. | AB2: https://smartlabel.labelinsight.com/product/18609278/other/instructions https://smartlabel.labelinsight.com/product/18609278/nutrition
A3: zw-002 | B3: Healthy Choice | C3: Lemon Parmesan Chicken | D3: 072655003217 | E3: frozen_tray | F3: 11 | G3: 311 | H3: =IF(G3<>"",G3,IF(F3<>"",ROUND(F3*28.3495,0),"")) -> 311 | L3: 0 | M3: =IF(H3="","",H3+L3) -> 311 | N3: =IF(OR(K3="",M3=""),"",IF(J3<>"",K3/J3*H3/M3,IF(I3<>"",K3*I3/M3,""))) | O3: =IF(N3="","",IF(N3<FoodClasses!$C$2,"lean",IF(N3<FoodClasses!$C$3,"medium","fatty"))) | P3: frozen | Q3: pp_container | R3: unknown | S3: Material not stated; confirm by photo (black = CPET, clear or white = PP). | T3: 1100 | U3: complete | V3: no | W3: None given. Label says to adjust times for your appliance. | X3: Cook only one at a time | Keep frozen, do not thaw | Z3: Film-covered tray (film is lifted and replaced mid-cook). Material not stated. | AA3: nutrition page returned a server error on two attempts | AB3: https://smartlabel.labelinsight.com/product/18859044/other/instructions
A4: zw-003 | B4: Marie Callender's | C4: Cajun Style Chicken Alfredo Bowl | D4: 021131000226 | E4: frozen_tray | F4: 11 | G4: 312 | H4: =IF(G4<>"",G4,IF(F4<>"",ROUND(F4*28.3495,0),"")) -> 312 | I4: 1 | J4: 312 | K4: 16 | L4: 0 | M4: =IF(H4="","",H4+L4) -> 312 | N4: =IF(OR(K4="",M4=""),"",IF(J4<>"",K4/J4*H4/M4,IF(I4<>"",K4*I4/M4,""))) -> 0.051282051 | O4: =IF(N4="","",IF(N4<FoodClasses!$C$2,"lean",IF(N4<FoodClasses!$C$3,"medium","fatty"))) -> medium | P4: frozen | Q4: cpet_tray | R4: inferred | S4: Oven-safe at 375 F with film on. | T4: 1100 | U4: complete | V4: no | W4: None given. | X4: Do not prepare in toaster oven | Do not remove film before oven cooking | Cook only one at a time | Keep frozen, do not thaw | Y4: 375°F, leave film on, on baking sheet 50 min, stand 2 min, stir. | Z4: Film-covered bowl tray; oven-safe per directions (baked at 375°F with film on). Material not stated. | AA4: no microwave stand time listed on label | AB4: https://smartlabel.labelinsight.com/product/15972825/other/instructions https://smartlabel.labelinsight.com/product/15972825/nutrition
A5: zw-004 | B5: Marie Callender's | C5: Fettuccini With Chicken & Broccoli Dinner | D5: 021131504755 | E5: frozen_tray | F5: 13 | G5: 369 | H5: =IF(G5<>"",G5,IF(F5<>"",ROUND(F5*28.3495,0),"")) -> 369 | I5: 1 | J5: 369 | K5: 18 | L5: 0 | M5: =IF(H5="","",H5+L5) -> 369 | N5: =IF(OR(K5="",M5=""),"",IF(J5<>"",K5/J5*H5/M5,IF(I5<>"",K5*I5/M5,""))) -> 0.048780488 | O5: =IF(N5="","",IF(N5<FoodClasses!$C$2,"lean",IF(N5<FoodClasses!$C$3,"medium","fatty"))) -> medium | P5: frozen | Q5: cpet_tray | R5: inferred | S5: Oven directions use the same tray at 350 F. | T5: 1100 | U5: complete | V5: no | W5: None given. | X5: Do not prepare in toaster oven | Cook only one at a time | Keep frozen, do not thaw | Y5: 350°F, vent film corner, on baking sheet 45-48 min, stand 2 min, stir. | Z5: Film-sealed tray with vent corner marked 'Push here to open'. Material not stated. | AB5: https://smartlabel.labelinsight.com/product/6903342/other/instructions https://smartlabel.labelinsight.com/product/6903342/nutrition
A6: zw-005 | B6: Stouffer's | C6: Classic Meatloaf | E6: frozen_tray | F6: 16 | H6: =IF(G6<>"",G6,IF(F6<>"",ROUND(F6*28.3495,0),"")) -> 454 | I6: 2 | J6: 226 | K6: 9 | L6: 0 | M6: =IF(H6="","",H6+L6) -> 454 | N6: =IF(OR(K6="",M6=""),"",IF(J6<>"",K6/J6*H6/M6,IF(I6<>"",K6*I6/M6,""))) -> 0.039823009 | O6: =IF(N6="","",IF(N6<FoodClasses!$C$2,"lean",IF(N6<FoodClasses!$C$3,"medium","fatty"))) -> medium | P6: frozen | Q6: pp_container | R6: unknown | S6: Stouffer's uses both plastic trays (no black pigment) and pressed paper trays; microwave-only label; confirm by photo [S68]. | T6: 1100 | U6: complete | V6: no | W6: None given. | X6: Do not reheat tray | Do not prepare in toaster oven | Z6: Film-covered tray; label says not to reheat the tray. Material not stated. | AA6: retailer copy of label; directions may be abridged (no mid-cook stir step shown) | UPC not shown | AB6: https://www.safeway.com/shop/pd/stouffers-classic-meatloaf-frozen-meal-16-oz/960010754
A7: zw-006 | B7: Stouffer's | C7: Macaroni & Cheese (single serve) | D7: 00013800103406 | E7: frozen_tray | F7: 12 | G7: 340 | H7: =IF(G7<>"",G7,IF(F7<>"",ROUND(F7*28.3495,0),"")) -> 340 | I7: 1 | J7: 340 | K7: 21 | L7: 0 | M7: =IF(H7="","",H7+L7) -> 340 | N7: =IF(OR(K7="",M7=""),"",IF(J7<>"",K7/J7*H7/M7,IF(I7<>"",K7*I7/M7,""))) -> 0.061764706 | O7: =IF(N7="","",IF(N7<FoodClasses!$C$2,"lean",IF(N7<FoodClasses!$C$3,"medium","fatty"))) -> medium | P7: frozen | Q7: paperboard_tray | R7: inferred | S7: Stouffer's says single-serve trays changed from plastic to paper [S68]; coating not stated. | U7: partial | V7: no | X7: Do not prepare in toaster oven | Do not reheat tray | Z7: Carton opened by 'push in, pull out'; tray must not be reheated. Material not stated. | AA7: only total time (5.5 min) available; venting, stir and stand steps and wattage missing; stouffers.com page failed to load | AB7: https://www.heb.com/product-detail/stouffer-s-mac-cheese-frozen-meal/29054 https://www.shoprite.com/sm/delivery/rsid/256/product/stouffers-mac-&-cheese-12-oz-id-00013800103406
A8: zw-007 | B8: Lean Cuisine | C8: Protein Kick Spaghetti with Meat Sauce | E8: frozen_tray | F8: 11.5 | H8: =IF(G8<>"",G8,IF(F8<>"",ROUND(F8*28.3495,0),"")) -> 326 | I8: 1 | K8: 4 | L8: 0 | M8: =IF(H8="","",H8+L8) -> 326 | N8: =IF(OR(K8="",M8=""),"",IF(J8<>"",K8/J8*H8/M8,IF(I8<>"",K8*I8/M8,""))) -> 0.012269939 | O8: =IF(N8="","",IF(N8<FoodClasses!$C$2,"lean",IF(N8<FoodClasses!$C$3,"medium","fatty"))) -> lean | P8: frozen | Q8: pp_container | R8: inferred | S8: Lean Cuisine FAQ says plastic trays [S69]; microwave-only directions point to PP. | T8: 1100 | U8: complete | V8: no | W8: None given. Label says ovens vary. | X8: Do not prepare in toaster oven | Do not reheat tray | Z8: Uncolored plastic tray, recyclable in communities that accept them (per page). Resin code not stated. | AA8: UPC not shown | leancuisine.com product page failed to load | AB8: https://preview.hannaford.com/groceries/frozen/frozen-dinners-meals/pasta-frozen-meals/lean-cuisine-protein-kick-spaghetti-with-meat-sauce-frozen-meal-115-oz-box.html
A9: zw-008 | B9: Hungry-Man | C9: Selects Boneless Fried Chicken and Ham | D9: 658276202941 | E9: frozen_tray | F9: 16 | G9: 454 | H9: =IF(G9<>"",G9,IF(F9<>"",ROUND(F9*28.3495,0),"")) -> 454 | I9: 1 | J9: 454 | K9: 21 | L9: 0 | M9: =IF(H9="","",H9+L9) -> 454 | N9: =IF(OR(K9="",M9=""),"",IF(J9<>"",K9/J9*H9/M9,IF(I9<>"",K9*I9/M9,""))) -> 0.046255507 | O9: =IF(N9="","",IF(N9<FoodClasses!$C$2,"lean",IF(N9<FoodClasses!$C$3,"medium","fatty"))) -> medium | P9: frozen | Q9: cpet_tray | R9: inferred | S9: Oven directions at 350 F in the same tray. | T9: 1100 | U9: complete | V9: no | W9: None given. | X9: Do not prepare in toaster oven | Cook only one at a time | Keep frozen, do not thaw | Y9: 350°F, remove dessert film, slit entree film, on baking sheet 40-45 min, stand 2 min. | Z9: Multi-compartment tray with separate film areas over dessert and entree. Material not stated. | AB9: https://smartlabel.labelinsight.com/product/17238176/other/instructions https://smartlabel.labelinsight.com/product/17238176/nutrition
A10: zw-009 | B10: Healthy Choice | C10: Power Bowls Spicy Steak Burrito Bowl | D10: 072655006782 | E10: frozen_tray | F10: 9.25 | G10: 262 | H10: =IF(G10<>"",G10,IF(F10<>"",ROUND(F10*28.3495,0),"")) -> 262 | I10: 1 | J10: 262 | K10: 4.5 | L10: 0 | M10: =IF(H10="","",H10+L10) -> 262 | N10: =IF(OR(K10="",M10=""),"",IF(J10<>"",K10/J10*H10/M10,IF(I10<>"",K10*I10/M10,""))) -> 0.017175573 | O10: =IF(N10="","",IF(N10<FoodClasses!$C$2,"lean",IF(N10<FoodClasses!$C$3,"medium","fatty"))) -> lean | P10: frozen | Q10: pp_container | R10: inferred | S10: Microwave-only bowl; label forbids oven use. | T10: 1100 | U10: complete | V10: no | W10: None given. | X10: DO NOT cook in conventional or toaster ovens (microwave-only product) | Do not use if film seal is broken | Cook only one at a time | Z10: Film-sealed bowl; microwave only (label forbids conventional oven). Material not stated. | AA10: calorie value (180) looks low for a 262 g bowl; verify against package | AB10: https://smartlabel.labelinsight.com/product/14931912/other/instructions https://smartlabel.labelinsight.com/product/14931912/nutrition
A11: zw-010 | B11: Frontera | C11: Cheese Enchiladas with Red Enchilada Sauce | D11: 604183000194 | E11: frozen_tray | F11: 9 | G11: 255 | H11: =IF(G11<>"",G11,IF(F11<>"",ROUND(F11*28.3495,0),"")) -> 255 | I11: 1 | J11: 255 | K11: 15 | L11: 0 | M11: =IF(H11="","",H11+L11) -> 255 | N11: =IF(OR(K11="",M11=""),"",IF(J11<>"",K11/J11*H11/M11,IF(I11<>"",K11*I11/M11,""))) -> 0.058823529 | O11: =IF(N11="","",IF(N11<FoodClasses!$C$2,"lean",IF(N11<FoodClasses!$C$3,"medium","fatty"))) -> medium | P11: frozen | Q11: cpet_tray | R11: inferred | S11: Oven directions in the same tray at 350 F. | T11: 1100 | U11: complete | V11: no | W11: None given. | X11: Do not prepare in toaster oven | Cook only one at a time | Keep frozen, do not thaw | Y11: 350°F, remove film, cover with foil, on baking sheet 40 min, uncover 5 min, stand 1 min. | Z11: Tray in carton ('Push here to open'). Material not stated. | AB11: https://smartlabel.labelinsight.com/product/17883027/other/instructions https://smartlabel.labelinsight.com/product/17883027/nutrition
A12: zw-011 | B12: Healthy Choice | C12: Cafe Steamers BBQ-Seasoned Steak & Potatoes | E12: frozen_tray | F12: 9.5 | H12: =IF(G12<>"",G12,IF(F12<>"",ROUND(F12*28.3495,0),"")) -> 269 | I12: 1 | K12: 4 | L12: 0 | M12: =IF(H12="","",H12+L12) -> 269 | N12: =IF(OR(K12="",M12=""),"",IF(J12<>"",K12/J12*H12/M12,IF(I12<>"",K12*I12/M12,""))) -> 0.014869888 | O12: =IF(N12="","",IF(N12<FoodClasses!$C$2,"lean",IF(N12<FoodClasses!$C$3,"medium","fatty"))) -> lean | P12: frozen | Q12: pp_container | R12: unknown | S12: Two-part steamer bowl; material not stated. | U12: partial | V12: no | Z12: Two-compartment steamer bowl: steaming basket over a separate sauce bowl. Material not stated. | AA12: taken from retailer description; wattage, venting and stand time missing | UPC not shown | AB12: https://www.heb.com/product-detail/healthy-choice-caf-steamers-bbq-seasoned-steak-potatoes-frozen-meal/1042876
A13: zw-012 | B13: Amy's | C13: Amy's Bowls Mexican Casserole | E13: frozen_tray | F13: 9.5 | H13: =IF(G13<>"",G13,IF(F13<>"",ROUND(F13*28.3495,0),"")) -> 269 | I13: 1 | J13: 269 | K13: 16 | L13: 0 | M13: =IF(H13="","",H13+L13) -> 269 | N13: =IF(OR(K13="",M13=""),"",IF(J13<>"",K13/J13*H13/M13,IF(I13<>"",K13*I13/M13,""))) -> 0.059479554 | O13: =IF(N13="","",IF(N13<FoodClasses!$C$2,"lean",IF(N13<FoodClasses!$C$3,"medium","fatty"))) -> medium | P13: frozen | Q13: cpet_tray | R13: unknown | S13: Amy's bowls go into the conventional oven; material not stated. Confirm by photo. | U13: none | V13: no | AA13: amys.com product page failed to load; Wegmans and H-E-B pages show an empty Instructions section | photograph box for directions and tray info | AB13: https://www.wegmans.com/shop/product/261725-Mexican-Casserole
A14: zw-013 | B14: Marie Callender's | C14: Turkey Pot Pie | D14: 021131501143 | E14: frozen_tray | F14: 10 | G14: 283 | H14: =IF(G14<>"",G14,IF(F14<>"",ROUND(F14*28.3495,0),"")) -> 283 | I14: 1 | J14: 283 | K14: 31 | L14: 0 | M14: =IF(H14="","",H14+L14) -> 283 | N14: =IF(OR(K14="",M14=""),"",IF(J14<>"",K14/J14*H14/M14,IF(I14<>"",K14*I14/M14,""))) -> 0.10954064 | O14: =IF(N14="","",IF(N14<FoodClasses!$C$2,"lean",IF(N14<FoodClasses!$C$3,"medium","fatty"))) -> fatty | P14: frozen | Q14: pet_board_tray | R14: inferred | S14: Paperboard tray used in a 400 F oven; ovenable board carries a PET coating [S60]. | T14: 1100 | U14: complete | V14: no | W14: Microwaves below 1100 W are not recommended; the pie may not cook through. Use the conventional oven instead. | X14: Not recommended in microwaves under 1100 W | Do not prepare in toaster oven | Cook only one at a time | Y14: 400°F, remove from outer carton, keep in paper tray, foil strip around crust edge, on baking sheet 48-52 min, stand 5 min. | Z14: Outer carton plus paper (paperboard) tray; microwave in opened carton, oven in paper tray. | AB14: https://smartlabel.labelinsight.com/product/4662734/other/instructions https://smartlabel.labelinsight.com/product/4662734/nutrition
A15: zw-014 | B15: Marie Callender's | C15: Creamy Parmesan Chicken Pot Pie | D15: 021131506964 | E15: frozen_tray | F15: 15 | G15: 425 | H15: =IF(G15<>"",G15,IF(F15<>"",ROUND(F15*28.3495,0),"")) -> 425 | I15: 2 | J15: 200 | K15: 27 | L15: 0 | M15: =IF(H15="","",H15+L15) -> 425 | N15: =IF(OR(K15="",M15=""),"",IF(J15<>"",K15/J15*H15/M15,IF(I15<>"",K15*I15/M15,""))) -> 0.135 | O15: =IF(N15="","",IF(N15<FoodClasses!$C$2,"lean",IF(N15<FoodClasses!$C$3,"medium","fatty"))) -> fatty | P15: frozen | Q15: pet_board_tray | R15: inferred | S15: Paperboard tray used in a 400 F oven; ovenable board carries a PET coating [S60]. | T15: 1100 | U15: complete | V15: no | W15: Do not microwave in ovens below 1100 W; use the conventional oven instead. | X15: Do not microwave in ovens under 1100 W | Do not prepare in toaster oven | Cook only one at a time | Y15: 400°F, keep in paper tray, foil strip around crust edge, on baking sheet 60-63 min, stand 5 min. | Z15: Outer carton plus paper (paperboard) tray. | AA15: servings per container listed as 'about 2' | AB15: https://smartlabel.labelinsight.com/product/4662724/other/instructions https://smartlabel.labelinsight.com/product/4662724/nutrition
A16: zw-015 | B16: Kraft | C16: Easy Mac Original Flavor Mac & Cheese Cups | E16: cup_bowl | F16: 2.05 | H16: =IF(G16<>"",G16,IF(F16<>"",ROUND(F16*28.3495,0),"")) -> 58 | I16: 1 | K16: 3.5 | L16: 110 | M16: =IF(H16="","",H16+L16) -> 168 | N16: =IF(OR(K16="",M16=""),"",IF(J16<>"",K16/J16*H16/M16,IF(I16<>"",K16*I16/M16,""))) -> 0.020833333 | O16: =IF(N16="","",IF(N16<FoodClasses!$C$2,"lean",IF(N16<FoodClasses!$C$3,"medium","fatty"))) -> lean | P16: shelf | Q16: pp_container | R16: inferred | S16: Microwavable plastic cup; check the resin code under the cup. | U16: partial | V16: no | X16: Cup and contents get very hot; keep children from burns | Z16: Single-serve microwavable cup with fill line. Material not stated. | AA16: wattage, stand time and power level not shown | UPC not shown | Sold as a 4-cup pack; nutrition is per cup and the app treats one cup as the product. | AB16: https://www.heb.com/product-detail/kraft-easy-mac-original-flavor-mac-and-cheese-cups/1070769
A17: zw-016 | B17: Maruchan | C17: Instant Lunch Ramen Noodle Soup, Chicken Flavor | E17: cup_bowl | F17: 2.25 | H17: =IF(G17<>"",G17,IF(F17<>"",ROUND(F17*28.3495,0),"")) -> 64 | L17: 300 | M17: =IF(H17="","",H17+L17) -> 364 | N17: =IF(OR(K17="",M17=""),"",IF(J17<>"",K17/J17*H17/M17,IF(I17<>"",K17*I17/M17,""))) | O17: =IF(N17="","",IF(N17<FoodClasses!$C$2,"lean",IF(N17<FoodClasses!$C$3,"medium","fatty"))) | P17: shelf | Q17: eps_foam | R17: label | S17: Label says do not microwave; check whether the cup is foam or paper. | U17: not_applicable | V17: yes | X17: Do not microwave | Z17: Single-serve cup with peel lid and inside fill line. Material not stated on source pages. | AA17: nutrition not shown on readable pages | good negative example: cup-shaped but labeled do not microwave | AB17: https://www.ubereats.com/store/safeway-2980-e-capitol-expy/5-N2W3K9WEqK_hLD35hwVQ/c3297a1d-4fb9-53f4-a254-36d1fa306f6f/922e7cae-c81f-4bba-82fa-5e9f19cfaffd/eda8ec7f-dc34-5bd1-ab34-0b8aab8f923f https://www.heb.com/product-detail/maruchan-instant-lunch-ramen-noodle-soup-cups-chicken-flavor/133669
A18: zw-017 | B18: Nissin | C18: Cup Noodles Chicken Flavor | E18: cup_bowl | F18: 2.25 | H18: =IF(G18<>"",G18,IF(F18<>"",ROUND(F18*28.3495,0),"")) -> 64 | I18: 1 | K18: 11 | L18: 300 | M18: =IF(H18="","",H18+L18) -> 364 | N18: =IF(OR(K18="",M18=""),"",IF(J18<>"",K18/J18*H18/M18,IF(I18<>"",K18*I18/M18,""))) -> 0.03021978 | O18: =IF(N18="","",IF(N18<FoodClasses!$C$2,"lean",IF(N18<FoodClasses!$C$3,"medium","fatty"))) -> medium | P18: shelf | Q18: paper_cup | R18: label | S18: Paper cup since 2024. | U18: partial | V18: no | Z18: Paper cup that replaced the polystyrene cup in 2024 and made the product microwavable in the package. | AA18: 2:15 microwave time comes from retailer listing and news report; wattage, fill line and stir/stand steps are on the lid and were not readable online | older polystyrene cups may still be in some stores; check the cup | AB18: https://heb.com/product-detail/nissin-cup-noodles-chicken-flavor-noodle-soup/160083 https://www.orderroombox.com/product/nissin-cup-noodles-chicken-flavor-ramen-noodle-soup-2/ https://www.foxla.com/news/cup-noodles-unveils-game-changing-packaging-update-for-2024
A19: zw-018 | B19: Campbell's | C19: Chunky Beef with Country Vegetables Soup, Microwavable Bowl | D19: 51000148787 | E19: cup_bowl | F19: 15.25 | H19: =IF(G19<>"",G19,IF(F19<>"",ROUND(F19*28.3495,0),"")) -> 432 | I19: 1 | K19: 3 | L19: 0 | M19: =IF(H19="","",H19+L19) -> 432 | N19: =IF(OR(K19="",M19=""),"",IF(J19<>"",K19/J19*H19/M19,IF(I19<>"",K19*I19/M19,""))) -> 0.0069444444 | O19: =IF(N19="","",IF(N19<FoodClasses!$C$2,"lean",IF(N19<FoodClasses!$C$3,"medium","fatty"))) -> lean | P19: shelf | Q19: pp_container | R19: inferred | S19: Microwave-safe plastic bowl; remove the metal peel lid first. | U19: partial | V19: no | W19: Label notes microwave ovens vary and uneven heating may cause popping or splattering. | X19: Plastic cap may be hot | Z19: Microwave-safe bowl with peel-off cover and plastic cap; eat directly from bowl. | AA19: no reference wattage stated | AB19: https://www.campbellsfoodservice.com/product/beef-with-country-vegetables-soup/
A20: zw-019 | B20: Campbell's | C20: Chunky Classic Chicken Noodle Soup, Microwavable Bowl | E20: cup_bowl | F20: 15.25 | H20: =IF(G20<>"",G20,IF(F20<>"",ROUND(F20*28.3495,0),"")) -> 432 | I20: 1 | K20: 5 | L20: 0 | M20: =IF(H20="","",H20+L20) -> 432 | N20: =IF(OR(K20="",M20=""),"",IF(J20<>"",K20/J20*H20/M20,IF(I20<>"",K20*I20/M20,""))) -> 0.011574074 | O20: =IF(N20="","",IF(N20<FoodClasses!$C$2,"lean",IF(N20<FoodClasses!$C$3,"medium","fatty"))) -> lean | P20: shelf | Q20: pp_container | R20: inferred | S20: Microwavable bowl with metal peel lid; remove the lid first. | U20: none | V20: no | X20: Do not reuse or reheat bowl | Metal edges are sharp | Do not buy if open or punctured | Z20: Microwavable bowl; page warns of sharp metal edges (peel-off lid) and says not to reuse or reheat the bowl. | AA20: Instructions section empty on H-E-B page; photograph bowl label | AB20: https://www.heb.com/product-detail/campbell-s-chunky-classic-chicken-noodle-soup/569232
A21: zw-020 | B21: Hormel | C21: Compleats Meatloaf & Gravy with Mashed Potatoes | E21: cup_bowl | F21: 9 | G21: 255 | H21: =IF(G21<>"",G21,IF(F21<>"",ROUND(F21*28.3495,0),"")) -> 255 | I21: 1 | K21: 13 | L21: 0 | M21: =IF(H21="","",H21+L21) -> 255 | N21: =IF(OR(K21="",M21=""),"",IF(J21<>"",K21/J21*H21/M21,IF(I21<>"",K21*I21/M21,""))) -> 0.050980392 | O21: =IF(N21="","",IF(N21<FoodClasses!$C$2,"lean",IF(N21<FoodClasses!$C$3,"medium","fatty"))) -> medium | P21: shelf | Q21: pp_container | R21: inferred | S21: Shelf-stable film-sealed tray. | U21: partial | V21: no | W21: Times approximate because microwaves vary. | X21: Not for conventional ovens | Z21: Shelf-stable microwavable tray sealed with plastic film. Material not stated. | AA21: no reference wattage | UPC not shown | page header says '9 oz can' but description is a film-sealed tray | AB21: https://preview.hannaford.com/groceries/soups-canned-goods/canned-meat/hormel-compleats-meatloaf-gravy-with-mashed-potatoes-microwavable-9-oz-can.html
A22: zw-021 | B22: Hormel | C22: Compleats Beef Tips & Gravy with Mashed Potatoes | E22: cup_bowl | F22: 9 | H22: =IF(G22<>"",G22,IF(F22<>"",ROUND(F22*28.3495,0),"")) -> 255 | I22: 1 | K22: 8 | L22: 0 | M22: =IF(H22="","",H22+L22) -> 255 | N22: =IF(OR(K22="",M22=""),"",IF(J22<>"",K22/J22*H22/M22,IF(I22<>"",K22*I22/M22,""))) -> 0.031372549 | O22: =IF(N22="","",IF(N22<FoodClasses!$C$2,"lean",IF(N22<FoodClasses!$C$3,"medium","fatty"))) -> medium | P22: shelf | Q22: pp_container | R22: inferred | S22: Shelf-stable tray. | U22: none | V22: no | Z22: Single tray (serving size listed as 1 tray). Material not stated. | AA22: Instructions section empty; photograph tray label | AB22: https://www.heb.com/product-detail/hormel-compleats-beef-tips-gravy-with-mashed-potatoes/1058929
A23: zw-022 | B23: Chef Boyardee | C23: Beefaroni Microwavable Bowl | E23: cup_bowl | F23: 7.5 | H23: =IF(G23<>"",G23,IF(F23<>"",ROUND(F23*28.3495,0),"")) -> 213 | L23: 0 | M23: =IF(H23="","",H23+L23) -> 213 | N23: =IF(OR(K23="",M23=""),"",IF(J23<>"",K23/J23*H23/M23,IF(I23<>"",K23*I23/M23,""))) | O23: =IF(N23="","",IF(N23<FoodClasses!$C$2,"lean",IF(N23<FoodClasses!$C$3,"medium","fatty"))) | P23: shelf | Q23: pp_container | R23: inferred | S23: Microwavable bowl. | U23: none | V23: no | AA23: placeholder: net weight from retailer listing titles only; SmartLabel instructions page returned server errors twice; Ahold retailer sites were in maintenance | photograph bowl label | AB23: https://smartlabel.labelinsight.com/product/13051379/other/claims
A24: zw-023 | B24: Birds Eye | C24: Steamfresh Seasoned Asian Medley | D24: 014500021632 | E24: steam_bag | F24: 10.8 | G24: 306 | H24: =IF(G24<>"",G24,IF(F24<>"",ROUND(F24*28.3495,0),"")) -> 306 | L24: 0 | M24: =IF(H24="","",H24+L24) -> 306 | N24: =IF(OR(K24="",M24=""),"",IF(J24<>"",K24/J24*H24/M24,IF(I24<>"",K24*I24/M24,""))) | O24: =IF(N24="","",IF(N24<FoodClasses!$C$2,"lean",IF(N24<FoodClasses!$C$3,"medium","fatty"))) | P24: frozen | Q24: steam_bag | R24: label | S24: Steam bag. | U24: complete | V24: no | W24: Below 800 W, use stovetop directions instead. | X24: Do not puncture bag | Do not thaw | Cook only one at a time | Z24: Microwave-safe steam bag with built-in vent; bag inflates and may whistle; tear notch and corner tabs. | AA24: nutrition page returned a server error | AB24: https://smartlabel.labelinsight.com/product/6823283/other/instructions
A25: zw-024 | B25: Birds Eye | C25: Steamfresh Power Blend Hawaiian Style | D25: 014500016676 | E25: steam_bag | F25: 12.8 | G25: 363 | H25: =IF(G25<>"",G25,IF(F25<>"",ROUND(F25*28.3495,0),"")) -> 363 | I25: 1 | J25: 363 | K25: 5 | L25: 0 | M25: =IF(H25="","",H25+L25) -> 363 | N25: =IF(OR(K25="",M25=""),"",IF(J25<>"",K25/J25*H25/M25,IF(I25<>"",K25*I25/M25,""))) -> 0.013774105 | O25: =IF(N25="","",IF(N25<FoodClasses!$C$2,"lean",IF(N25<FoodClasses!$C$3,"medium","fatty"))) -> lean | P25: frozen | Q25: steam_bag | R25: label | S25: Steam bag. | U25: complete | V25: no | W25: Below 800 W, use stovetop directions instead. | X25: Do not pierce bag | Do not thaw | Cook only one at a time | Z25: Microwave-safe steam bag with vent; inflates while cooking, may whistle. | AB25: https://smartlabel.labelinsight.com/product/6100979/other/instructions https://smartlabel.labelinsight.com/product/6100979/nutrition
A26: zw-025 | B26: Birds Eye | C26: Steamfresh Power Blend Italian Style | D26: 014500015822 | E26: steam_bag | F26: 11.5 | G26: 326 | H26: =IF(G26<>"",G26,IF(F26<>"",ROUND(F26*28.3495,0),"")) -> 326 | I26: 1 | J26: 326 | K26: 6 | L26: 0 | M26: =IF(H26="","",H26+L26) -> 326 | N26: =IF(OR(K26="",M26=""),"",IF(J26<>"",K26/J26*H26/M26,IF(I26<>"",K26*I26/M26,""))) -> 0.018404908 | O26: =IF(N26="","",IF(N26<FoodClasses!$C$2,"lean",IF(N26<FoodClasses!$C$3,"medium","fatty"))) -> lean | P26: frozen | Q26: steam_bag | R26: label | S26: Steam bag. | T26: 1100 | U26: complete | V26: no | W26: None given; adjust for appliance. | X26: Do not pierce bag | Do not thaw | Cook only one bag at a time | Z26: Sealed microwave steam bag with vent; printed 'THIS SIDE UP', 'TEAR HERE', 'PICK UP HERE'. | AA26: same product line as zw-023/024 but uses a single 1100 W reference instead of a wattage table | AB26: https://smartlabel.labelinsight.com/product/13770749/other/instructions https://smartlabel.labelinsight.com/product/13770749/nutrition
A27: zw-026 | B27: Green Giant | C27: Riced Veggies Cauliflower & Broccoli | D27: 190569123118 | E27: steam_bag | F27: 10 | G27: 283 | H27: =IF(G27<>"",G27,IF(F27<>"",ROUND(F27*28.3495,0),"")) -> 283 | I27: 3 | K27: 0 | L27: 0 | M27: =IF(H27="","",H27+L27) -> 283 | N27: =IF(OR(K27="",M27=""),"",IF(J27<>"",K27/J27*H27/M27,IF(I27<>"",K27*I27/M27,""))) -> 0 | O27: =IF(N27="","",IF(N27<FoodClasses!$C$2,"lean",IF(N27<FoodClasses!$C$3,"medium","fatty"))) -> lean | P27: frozen | Q27: steam_bag | R27: label | S27: Steam bag. | T27: 1000 | U27: complete | V27: no | W27: 700 W: 7 min on HIGH. | X27: Do not thaw | Z27: Microwave-in bag cooked standing upright; vent not mentioned. | AA27: servings per container listed as 'about 3' | AB27: https://smartlabel.labelinsight.com/product/6822702/other/instructions https://smartlabel.labelinsight.com/product/6822702/nutrition
